Workbook

Sheet 1. How it works
A1: HIVE access model (proposal)
A3: The idea in one line | B3: Every person gets ONE access level, a SHORT list of on/off categories (about 15 instead of 83), and a SCOPE that says WHOSE information those categories apply to.
A5: 1. Access level | B5: Owner, Admin, or Staff. Fixed by HIVE. Sets the ceiling of what's possible. HRC committee members are Staff with the "HRC Committee" preset. See sheet 2.
A6: 2. Categories | B6: 18 broad switches (Billing, Documentation, Scheduling…). Each is Off / View / Edit. Edit = create, change, approve, and export. Sheet 7 explains exactly what each setting allows and doesn't allow.
A7: 3. Scope | B7: WHO the categories apply to: Whole agency, Assigned homes, Assigned staff, Assigned clients, or Only themselves. Homes, staff and clients can be combined. See sheet 4.
A8: 4. Preset | B8: A saved combination of level + categories + scope type, named by the agency ("Supervisor", "Manager", "Lead"…). Pick a preset when you hire; tweak per person if needed. See sheet 3.
A9: 5. Job title | B9: Free text for display (profile, roster, face sheet). Has NO effect on access.
A10: 6. Staff type | B10: DSP, Host Home Provider, etc. Drives which compliance items they owe. Has NO effect on access.
A12: Example | B12: Sarah is the Maple House manager. Level = Admin. Preset = Group Home Manager. Scope = Maple House. She sees billing, documentation, schedules and timesheets for every Maple House client and staffer, and nothing for anyone else in the company.
A14: How to read sheet 3 | B14: Green = Edit, Blue = View, Grey = Off, Purple = Owner only (can't be granted to anyone else). Presets are examples; agencies rename, copy and adjust them.
A15: Editing | B15: Every value cell has a dropdown, colors update when you change them, and the Lists tab controls what's in each dropdown. Blank rows and Custom preset columns are ready for new categories/presets.
A16: How to read sheet 5 | B16: Every one of today's 83 permissions, and which new category + action it folds into. Nothing is lost; it's regrouped.

Sheet 2. Access levels
A1: Level | B1: Who it's for | C1: What's locked / guaranteed | D1: Customizable? | E1: Default scope
A2: Owner | B2: Business owners and the few people who hold the keys. | C2: Always has everything; can't be edited or locked out. Only Owners: billing/subscription, agency settings, permissions, promoting/demoting Owners and Admins, deleting the agency. At least 1 Owner required. | D2: No. Owners are always full access. | E2: Whole agency (locked)
A3: Admin | B3: Anyone who works in the web dashboard: program managers, home managers, HR, billing, office. | C3: Can never touch Agency settings & permissions. Can't edit Owners. Can't give anyone a permission they don't have themselves. | D3: Yes: every category Off/View/Edit, plus scope. | E3: Set by preset
A4: Staff | B4: DSPs and other direct-care staff who use the phone app, plus HRC committee members (via the "HRC Committee" preset). | C4: Phone app only; no web dashboard. Can see only their own record and today's clients unless given a scope. | D4: Limited: categories up to View; Documentation up to Edit (e.g. a Lead DSP approving notes in the app); HRC up to Edit (HRC Committee preset). | E4: Only themselves

Sheet 3. Presets matrix
A1: Category | B1: What it covers | C1: Limited by scope? | D1: Owner | E1: Program Manager | F1: Group Home Manager | G1: HR / Office | H1: Billing | I1: DSP | J1: Lead DSP | K1: HRC Committee | L1: Custom preset 1 | M1: Custom preset 2 | N1: Custom preset 3
A2: Access level | D2: Owner | E2: Admin | F2: Admin | G2: Admin | H2: Admin | I2: Staff | J2: Staff | K2: Staff
A3: Scope (whose info) | D3: Whole agency (locked) | E3: Whole agency | F3: Assigned homes | G3: Whole agency (staff only) | H3: Whole agency | I3: Only themselves | J3: Assigned home | K3: Assigned clients
A4: Staff roster & profiles | B4: See the staff list, open profiles, edit names/phone/hire date/job title. | C4: Yes | D4: Edit | E4: Edit | F4: View | G4: Edit | H4: View | I4: Off | J4: View | K4: Off
A5: Hire & deactivate staff | B5: Add employee, upload roster, send invites, reset passwords, deactivate/reactivate. | C5: Yes | D5: Edit | E5: Edit | F5: Off | G5: Edit | H5: Off | I5: Off | J5: Off | K5: Off
A6: Staff compliance file & training | B6: Staff file items, evidence uploads, cert approvals, assigning training, courses. | C6: Yes | D6: Edit | E6: Edit | F6: View | G6: Edit | H6: Off | I6: Off | J6: Off | K6: Off
A7: Clients & charts | B7: Client list, chart, goals, client documents, intake. | C7: Yes | D7: Edit | E7: Edit | F7: Edit | G7: Off | H7: View | I7: Off | J7: View | K7: View
A8: Client medical & medications | B8: Diagnoses, medical info, medication list, eMAR admin. | C8: Yes | D8: Edit | E8: View | F8: View | G8: Off | H8: Off | I8: Off | J8: View | K8: View
A9: Documentation review | B9: Shift notes, daily logs, form submissions: read, correct, approve. | C9: Yes | D9: Edit | E9: Edit | F9: Edit | G9: Off | H9: View | I9: Off | J9: Edit | K9: Off
A10: Incidents | B10: Incident reports: read, manage, export. | C10: Yes | D10: Edit | E10: Edit | F10: Edit | G10: View | H10: Off | I10: Off | J10: View | K10: View
A11: HRC / rights restrictions | B11: Human Rights Committee reviews and rights-modification records. | C11: Yes | D11: Edit | E11: Edit | F11: View | G11: Off | H11: Off | I11: Off | J11: Off | K11: Edit
A12: Scheduling | B12: See the schedule, create/edit/delete shifts, approve swaps, recurring shifts. | C12: Yes | D12: Edit | E12: Edit | F12: Edit | G12: View | H12: View | I12: Off | J12: View | K12: Off
A13: Timesheets & EVV | B13: See/approve/edit timesheets, EVV export. | C13: Yes | D13: Edit | E13: Edit | F13: Edit | G13: View | H13: View | I13: Off | J13: View | K13: Off
A14: Billing | B14: Billing, claims, authorizations (1056), service codes. | C14: Yes | D14: Edit | E14: View | F14: View | G14: Off | H14: Edit | I14: Off | J14: Off | K14: Off
A15: Payroll | B15: Payroll runs and pay data. | C15: Yes | D15: Edit | E15: View | F15: Off | G15: Edit | H15: View | I15: Off | J15: Off | K15: Off
... A21: Phone app basics | B21: Clock in/out, own timesheets, shift notes, daily logs, forms, incidents, eMAR, own training/certs. | C21: Own work only | D21: On | E21: On | F21: On | G21: Off | H21: Off | I21: On | J21: On | K21: Off
A27: How to edit | B27: Click any Edit/View/Off cell, the Access level row, the Scope row, or the 'Limited by scope?' column: a dropdown arrow appears. Colors update automatically.
B28: Rename a preset or category by typing over its name (headers are plain text). Blank rows and the 'Custom preset' columns are ready for new ones.
B29: To change what's IN a dropdown (e.g. add 'Approve only' or a new scope option), edit the Lists tab. New options appear in the dropdowns right away.
A30: Legend | B30: Edit = create, change, approve, export. View = read only. Off = hidden. Owner only = cannot be granted to anyone else.
B31: Staff presets: View/Edit here happens inside the phone app, not the web dashboard. The HRC Committee preset lands on the HRC page instead of the phone app. See sheet 7 for what each setting means.

Sheet 4. Scope rules
A1: Scope option | B1: What they can see | C1: Example
A2: Whole agency | B2: Every client and staffer in the agency, for each category they have on. | C2: Program Manager sees billing for all homes.
A3: Assigned homes | B3: Everyone tied to the home(s) they're assigned: clients who live/are served there, staff on that home's team or scheduled there, and that home's shifts, timesheets, notes, incidents and billing. | C3: Maple House manager: all Maple House clients and staff; nothing from Oak House.
A4: Assigned staff | B4: Specific staff and/or admins picked by name (the Connecteam model). Unlocks THEIR records only: profile, schedule, timesheets, pay, compliance file, training — for whichever categories are on. Does NOT unlock the clients those staff serve. | C4: HR lead is assigned 3 office admins; a home manager is also assigned one floater DSP.
A5: Assigned clients | B5: Specific clients picked by name. Unlocks THEIR records only: chart, medical, notes/logs about them, incidents, HRC, billing — for whichever categories are on. Shows the names of staff who worked with them, but not those staff's full profiles or pay. | C5: A behavior specialist is assigned 4 clients across different homes.
A6: Combining | B6: Homes, assigned staff and assigned clients stack: the person sees everyone in ANY of their lists. Nothing is unlocked indirectly (seeing a staffer never reveals their clients, and seeing a client never reveals their staff's pay). | C6: Maple House manager + one floater DSP + one client who attends day program elsewhere.
A7: Only themselves | B7: Their own profile, schedule, timesheets and training, plus the clients on their shift today. | C7: A DSP on the phone app.
A9: Tricky case | B9: Suggested rule | C9: Why
A10: Staffer works at two homes | B10: Assign them to each manager (Assigned staff or via each home). Every assigned manager sees their full staff record, within what that manager's preset allows. | C10: Decided 2026-09-25: staff can be assigned to multiple managers.
A11: Floater / on-call DSP | B11: Add them to a manager as Assigned staff, or leave them whole-agency for Program Managers only. | C11: Avoids inventing a fake 'home' for floaters.
A12: Client moves homes | B12: The new home's manager gets the chart from the move date forward; the old manager keeps read-only history up to the move date. | C12: Billing and notes stay with the home that delivered the service.
A13: Client has services in two places (e.g. home + SEI day program) | B13: Assign the client to each manager who needs them. Every assigned manager sees the full client record, within what that manager's preset allows. | C13: Decided 2026-09-25: clients can be assigned to multiple managers.
... A15: Who can change scopes? | B15: Owners only (it's part of Agency settings & permissions). | C15: Stops a manager widening their own view.

Sheet 5. Old 83 to new
A1: Today's group | B1: Today's permission (as shown on profile) | C1: Internal key | D1: New category (dropdown) | E1: Counts as (dropdown) | F1: Note
A2: People & Files | B2: Invite staff | C2: invite_staff | D2: Hire & deactivate staff | E2: Edit
A3: People & Files | B3: View staff records | C3: view_staff_records | D3: Staff roster & profiles | E3: View
A4: People & Files | B4: Edit staff records | C4: edit_staff_records | D4: Staff roster & profiles | E4: Edit
A5: People & Files | B5: Manage staff roles | C5: manage_staff_roles | D5: Agency settings & permissions | E5: Owner only
A6: People & Files | B6: Deactivate staff | C6: deactivate_staff | D6: Hire & deactivate staff | E6: Edit
A7: People & Files | B7: View staff documents | C7: view_staff_documents | D7: Staff compliance file & training | E7: View
A8: People & Files | B8: Upload staff documents | C8: upload_staff_documents | D8: Staff compliance file & training | E8: Edit
A9: People & Files | B9: Approve staff documents | C9: approve_staff_documents | D9: Staff compliance file & training | E9: Edit
A10: People & Files | B10: View clients | C10: view_clients | D10: Clients & charts | E10: View
A11: People & Files | B11: Edit client records | C11: edit_client_records | D11: Clients & charts | E11: Edit
A12: People & Files | B12: Manage client intake | C12: manage_client_intake | D12: Clients & charts | E12: Edit
A13: People & Files | B13: View client medical info | C13: view_client_medical | D13: Client medical & medications | E13: View
... A21: People & Files | B21: Approve daily logs | C21: approve_daily_logs | D21: Documentation review | E21: Edit
A22: People & Files | B22: Manage forms | C22: manage_forms | D22: Agency settings & permissions | E22: Owner only | F22: Form builder is agency setup
A23: People & Files | B23: View form submissions | C23: view_form_submissions | D23: Documentation review | E23: View
A24: People & Files | B24: Approve form submissions | C24: approve_form_submissions | D24: Documentation review | E24: Edit
A25: People & Files | B25: View compliance dashboard | C25: view_compliance_dashboard | D25: Staff compliance file & training | E25: View
A26: People & Files | B26: File staff documents | C26: file_staff_documents | D26: Staff compliance file & training | E26: Edit
A27: People & Files | B27: Manage obligations | C27: manage_obligations | D27: Staff compliance file & training | E27: Edit
A28: People & Files | B28: View audit trail | C28: view_audit_trail | D28: Reports, analytics & audit trail | E28: View
A29: People & Files | B29: View incidents | C29: view_incidents | D29: Incidents | E29: View
A30: People & Files | B30: Manage incidents | C30: manage_incidents | D30: Incidents | E30: Edit
A31: People & Files | B31: Export incident reports | C31: export_incident_reports | D31: Incidents | E31: Edit
A32: People & Files | B32: Manage medications | C32: manage_medications | D32: Client medical & medications | E32: Edit
A33: People & Files | B33: View HRC | C33: view_hrc | D33: HRC / rights restrictions | E33: View
A34: People & Files | B34: Manage HRC | C34: manage_hrc | D34: HRC / rights restrictions | E34: Edit
... A39: People & Files | B39: Manage permissions | C39: manage_permissions | D39: Agency settings & permissions | E39: Owner only
A40: People & Files | B40: Manage roles & permissions (legacy) | C40: manage_roles | D40: Agency settings & permissions | E40: Owner only | F40: Legacy duplicate — retire
A41: People & Files | B41: Assign training | C41: assign_training | D41: Staff compliance file & training | E41: Edit
A42: People & Files | B42: Create courses | C42: create_courses | D42: Staff compliance file & training | E42: Edit
A43: People & Files | B43: Edit courses | C43: edit_courses | D43: Staff compliance file & training | E43: Edit
A44: People & Files | B44: Manage certifications | C44: manage_certifications | D44: Staff compliance file & training | E44: Edit
A45: People & Files | B45: Manage training programs | C45: manage_programs | D45: Staff compliance file & training | E45: Edit
A46: People & Files | B46: Approve external certifications | C46: approve_external_certs | D46: Staff compliance file & training | E46: Edit
A47: People & Files | B47: View team reports | C47: view_team_reports | D47: Staff compliance file & training | E47: View
A48: People & Files | B48: Manage organization (legacy) | C48: manage_organization | D48: Agency settings & permissions | E48: Owner only | F48: Legacy duplicate — retire
A49: People & Files | B49: View platform metrics | C49: view_platform_metrics | D49: (HIVE internal) | E49: Remove | F49: HIVE staff only; hide from agencies
A50: People & Files | B50: Manage all organizations | C50: manage_all_orgs | D50: (HIVE internal) | E50: Remove | F50: HIVE staff only; hide from agencies
A51: People & Files | B51: View referrals (CRM) | C51: view_referrals | D51: Hosts & referrals | E51: View
...

Sheet 6. Count check
A1: New category | B1: Old permissions folded in
A2: =IF('3. Presets matrix'!A4="","",'3. Presets matrix'!A4) | B2: =IF(A2="","",COUNTIF('5. Old 83 to new'!$D$2:$D$84,A2))
A3: =IF('3. Presets matrix'!A5="","",'3. Presets matrix'!A5) | B3: =IF(A3="","",COUNTIF('5. Old 83 to new'!$D$2:$D$84,A3))
A4: =IF('3. Presets matrix'!A6="","",'3. Presets matrix'!A6) | B4: =IF(A4="","",COUNTIF('5. Old 83 to new'!$D$2:$D$84,A4))
A5: =IF('3. Presets matrix'!A7="","",'3. Presets matrix'!A7) | B5: =IF(A5="","",COUNTIF('5. Old 83 to new'!$D$2:$D$84,A5))
A6: =IF('3. Presets matrix'!A8="","",'3. Presets matrix'!A8) | B6: =IF(A6="","",COUNTIF('5. Old 83 to new'!$D$2:$D$84,A6))
A7: =IF('3. Presets matrix'!A9="","",'3. Presets matrix'!A9) | B7: =IF(A7="","",COUNTIF('5. Old 83 to new'!$D$2:$D$84,A7))
A8: =IF('3. Presets matrix'!A10="","",'3. Presets matrix'!A10) | B8: =IF(A8="","",COUNTIF('5. Old 83 to new'!$D$2:$D$84,A8))
A9: =IF('3. Presets matrix'!A11="","",'3. Presets matrix'!A11) | B9: =IF(A9="","",COUNTIF('5. Old 83 to new'!$D$2:$D$84,A9))
A10: =IF('3. Presets matrix'!A12="","",'3. Presets matrix'!A12) | B10: =IF(A10="","",COUNTIF('5. Old 83 to new'!$D$2:$D$84,A10))
A11: =IF('3. Presets matrix'!A13="","",'3. Presets matrix'!A13) | B11: =IF(A11="","",COUNTIF('5. Old 83 to new'!$D$2:$D$84,A11))
A12: =IF('3. Presets matrix'!A14="","",'3. Presets matrix'!A14) | B12: =IF(A12="","",COUNTIF('5. Old 83 to new'!$D$2:$D$84,A12))
A13: =IF('3. Presets matrix'!A15="","",'3. Presets matrix'!A15) | B13: =IF(A13="","",COUNTIF('5. Old 83 to new'!$D$2:$D$84,A13))
... A23: =IF('3. Presets matrix'!A25="","",'3. Presets matrix'!A25) | B23: =IF(A23="","",COUNTIF('5. Old 83 to new'!$D$2:$D$84,A23))
A24: ="(HIVE internal)" | B24: =IF(A24="","",COUNTIF('5. Old 83 to new'!$D$2:$D$84,A24))
A25: Total | B25: =SUM(B2:B24)
A27: Updates automatically when you rename a category on the Presets matrix or change a row on sheet 5. Total should stay 83.

Sheet 7. What each setting means
A1: What each setting allows and doesn't allow. This is the text HIVE shows in the drop-down under each permission. Edit any cell; the platform copy is built from this sheet. Everything applies only to people inside the person's scope.
A2: Category | B2: What it covers | C2: Off | D2: View | E2: Edit
A3: Staff roster & profiles | B3: The staff list and each person's profile. | C3: Can't see the staff list or open anyone's profile. | D3: Can see the staff list and open profiles (contact info, hire date, job title, home). Can't change anything. | E3: Everything in View, plus edit names, phone, email, hire date, job title and home. Can't hire, deactivate, or change anyone's access.
A4: Hire & deactivate staff | B4: Bringing people on and taking them off. | C4: Can't add, invite, or deactivate anyone. | D4: Can see pending invites and deactivated staff. Can't add, invite, reset passwords, or deactivate. | E4: Can add employees, upload a roster, send and resend invites, reset passwords, deactivate and reactivate. Can't choose anyone's access level or preset (Owners only).
A5: Staff compliance file & training | B5: Staff file items, evidence, certifications, training. | C5: Can't see anyone's staff file, certifications or training. | D5: Can see staff file items, uploaded evidence, certification status, training progress and team compliance reports. Can't upload, approve, or assign. | E5: Can upload and file documents, approve certifications and evidence, assign training, create and edit courses, and manage obligations.
A6: Clients & charts | B6: The client list, charts, goals, documents, intake. | C6: Can't see clients (except the clients on their own shift, if Phone app basics is On). | D6: Can see the client list and open charts, goals, documents and intake info. Can't change anything. Medical info is a separate setting. | E6: Can add clients, edit charts, goals and documents, and run intake. Can't see medical info unless Client medical is also on.
A7: Client medical & medications | B7: Diagnoses, medical info, medication list, eMAR. | C7: Can't see diagnoses, medical info or medications. | D7: Can see diagnoses, medical info, the medication list and eMAR history. Can't change them. | E7: Can edit medical info and the medication list and manage eMAR. (Passing meds on a shift is part of Phone app basics.)
A8: Documentation review | B8: Other people's shift notes, daily logs, form submissions. | C8: Can't see other people's shift notes, daily logs or form submissions. | D8: Can read shift notes, daily logs and form submissions. Can't correct, send back, or approve them. | E8: Can read, correct, send back and approve shift notes, daily logs and form submissions.
A9: Incidents | B9: Incident reports after they're filed. | C9: Can't see incident reports. (Can still report one from the phone app if Phone app basics is On.) | D9: Can read incident reports. Can't update, close, or export them. | E9: Can manage incidents (follow-up, status, close) and export incident reports.
A10: HRC / rights restrictions | B10: Human Rights Committee reviews and rights-modification records. | C10: Can't see HRC reviews or rights-modification records. | D10: Can read HRC reviews and rights-modification records. Can't add, change, or record decisions. | E10: Can create and update HRC reviews, record decisions, and manage rights-modification records.
A11: Scheduling | B11: The shift schedule. | C11: Can't see the schedule (except their own shifts in the phone app). | D11: Can see the schedule. Can't create, change, or delete shifts. | E11: Can create, edit and delete shifts, set up recurring shifts, and approve swaps. HIVE still blocks shifts with no active authorization.
A12: Timesheets & EVV | B12: Other people's timesheets and EVV records. | C12: Can't see anyone else's timesheets. | D12: Can see timesheets and EVV records. Can't edit, approve, or export them. | E12: Can edit and approve timesheets and export EVV data.
A13: Billing | B13: Billing, claims, authorizations (1056), service codes. | C13: Can't see billing, claims, authorizations or service codes. | D13: Can see billing, claims, authorizations and service codes. Can't change or submit anything. | E13: Can manage billing and claims, authorizations and service codes.
... A20: Phone app basics | B20: The staff phone app for their own work. | C20: Can't use the phone app's work features. | D20: (On/Off only) | E20: On: can clock in/out, see own timesheets, write shift notes and daily logs, submit forms, report incidents, pass meds (eMAR), and do their own training and certs. Only their own work and today's clients.
A22: Blank rows below are for new categories.

Sheet Lists
A1: Permission values | B1: Phone values | C1: Access levels | D1: Scope options | E1: Limited by scope? | F1: Categories (auto from matrix) | G1: Counts as
A2: Edit | B2: On | C2: Owner | D2: Whole agency | E2: Yes | F2: =IF('3. Presets matrix'!A4="","",'3. Presets matrix'!A4) | G2: Edit
A3: View | B3: Off | C3: Admin | D3: Whole agency (locked) | E3: No — whole agency | F3: =IF('3. Presets matrix'!A5="","",'3. Presets matrix'!A5) | G3: View
A4: Off | C4: Staff | D4: Whole agency (staff only) | E4: Own work only | F4: =IF('3. Presets matrix'!A6="","",'3. Presets matrix'!A6) | G4: On
A5: Owner only | D5: Whole agency (clients only) | F5: =IF('3. Presets matrix'!A7="","",'3. Presets matrix'!A7) | G5: Owner only
D6: Assigned homes | F6: =IF('3. Presets matrix'!A8="","",'3. Presets matrix'!A8) | G6: Remove
D7: Assigned home | F7: =IF('3. Presets matrix'!A9="","",'3. Presets matrix'!A9)
D8: Assigned staff | F8: =IF('3. Presets matrix'!A10="","",'3. Presets matrix'!A10)
D9: Assigned clients | F9: =IF('3. Presets matrix'!A11="","",'3. Presets matrix'!A11)
D10: Homes + assigned staff | F10: =IF('3. Presets matrix'!A12="","",'3. Presets matrix'!A12)
D11: Homes + assigned clients | F11: =IF('3. Presets matrix'!A13="","",'3. Presets matrix'!A13)
D12: Homes + staff + clients | F12: =IF('3. Presets matrix'!A14="","",'3. Presets matrix'!A14)
D13: Assigned staff + clients | F13: =IF('3. Presets matrix'!A15="","",'3. Presets matrix'!A15)
D14: Only themselves | F14: =IF('3. Presets matrix'!A16="","",'3. Presets matrix'!A16)
F15: =IF('3. Presets matrix'!A17="","",'3. Presets matrix'!A17)
F16: =IF('3. Presets matrix'!A18="","",'3. Presets matrix'!A18)
F17: =IF('3. Presets matrix'!A19="","",'3. Presets matrix'!A19)
F18: =IF('3. Presets matrix'!A20="","",'3. Presets matrix'!A20)
F19: =IF('3. Presets matrix'!A21="","",'3. Presets matrix'!A21)
F20: =IF('3. Presets matrix'!A22="","",'3. Presets matrix'!A22)
F21: =IF('3. Presets matrix'!A23="","",'3. Presets matrix'!A23)
F22: =IF('3. Presets matrix'!A24="","",'3. Presets matrix'!A24)
F23: =IF('3. Presets matrix'!A25="","",'3. Presets matrix'!A25)
F24: (HIVE internal)
A36: Type new options at the bottom of any column (A–E, G) and they show up in the dropdowns. Column F copies the category names from the Presets matrix.
